Workbook
Name tagsum: '[1]lookup tables'!$A$51:$B$383
Name tagsum2: '[1]lookup tables'!$E$57:$F$198

Sheet Esc by age data
A1: Stuff in Yellow is Scale Ages. IF NOT AGES PRESENT FOR A ROW, leave blank. IF AT LEAST ONE SAMPLE, enter 0 for other cells.
A2: Stuff in blue is calculated, but will change when real data is added
A3: Green are CWT ages
A4: I have not added calculations for precision or to correct scale aging error
A5: Hatchery Unclipped - Use Unclipped No Petersen Tag results since Brood is collected with tangle nets off of Redds and may be more closely similar to deadpitch than application
G6: Age Samples from Scales or CWTs (only for AFC strata) | L6: Uncorrected Escapement by Age and Stratum
A7: Location | B7: Stratum | C7: AFC Status | D7: Petersen Tagged | E7: Year | F7: Stratum Estimate | G7: Age-3 | H7: Age-4 | I7: Age-5 | J7: Age-6 | K7: Raw_ESC_Age-3 | L7: Raw_ESC_Age-4 | M7: Raw_ESC_Age-5 | N7: Raw_ESC_Age-6 | O7: =K7 -> Raw_ESC_Age-3 | P7: =L7 -> Raw_ESC_Age-4 | Q7: =M7 -> Raw_ESC_Age-5 | R7: =N7 -> Raw_ESC_Age-6
A9: River | B9: Adult Males | C9: Clipped | D9: NA | E9: 2010 | F9: 0
A10: River | B10: Adult Males | C10: Unclipped | D10: Petersen Tagged | E10: 2010 | F10: 833 | G10: 1 | H10: 102 | I10: 39 | J10: 2 | K10: =+(G10/(SUM($G10:$J10)))*$F10 -> 5.7847222 | L10: =+(H10/(SUM($G10:$J10)))*$F10 -> 590.04167 | M10: =+(I10/(SUM($G10:$J10)))*$F10 -> 225.60417 | N10: =+(J10/(SUM($G10:$J10)))*$F10 -> 11.569444
A11: River | B11: Adult Males | C11: Unclipped | D11: No Petersen Tag | E11: 2010 | F11: =+F14-SUM(F9:F10) -> 2845 | G11: 1 | H11: 55 | I11: 29 | J11: 4 | K11: =+(G11/(SUM($G11:$J11)))*$F11 -> 31.966292 | L11: =+(H11/(SUM($G11:$J11)))*$F11 -> 1758.1461 | M11: =+(I11/(SUM($G11:$J11)))*$F11 -> 927.02247 | N11: =+(J11/(SUM($G11:$J11)))*$F11 -> 127.86517
A12: Hatchery | B12: Adult Males | C12: Clipped | D12: No Petersen Tag | E12: 2010 | K12: =+IF($F12=0,0,(G12/(SUM($G12:$J12)))*$F12) -> 0 | L12: =+IF($F12=0,0,(H12/(SUM($G12:$J12)))*$F12) -> 0 | M12: =+IF($F12=0,0,(I12/(SUM($G12:$J12)))*$F12) -> 0 | N12: =+IF($F12=0,0,(J12/(SUM($G12:$J12)))*$F12) -> 0
A13: Hatchery | B13: Adult Males | C13: Unclipped | D13: No Petersen Tag | E13: 2010 | K13: =+IF(G13="",(G11/(SUM($G11:$J11)))*$F13,(G13/(SUM($G13:$J13)))*$F13) -> 0 | L13: =+IF(H13="",(H11/(SUM($G11:$J11)))*$F13,(H13/(SUM($G13:$J13)))*$F13) -> 0 | M13: =+IF(I13="",(I11/(SUM($G11:$J11)))*$F13,(I13/(SUM($G13:$J13)))*$F13) -> 0 | N13: =+IF(J13="",(J11/(SUM($G11:$J11)))*$F13,(J13/(SUM($G13:$J13)))*$F13) -> 0
A14: River | B14: Adult Males | C14: both | D14: both | E14: 2010 | F14: 3678 | K14: =+SUM(K9:K11) -> 37.751014 | L14: =+SUM(L9:L11) -> 2348.1877 | M14: =+SUM(M9:M11) -> 1152.6266 | N14: =+SUM(N9:N11) -> 139.43461 | O14: =K14/$F14 -> 0.010264006 | P14: =L14/$F14 -> 0.63844147 | Q14: =M14/$F14 -> 0.31338408 | R14: =N14/$F14 -> 0.037910444
A15: River and Hatchery | B15: Adult Males | C15: both | D15: both | E15: 2010 | F15: =F14+SUM(F12:F13) -> 3678 | K15: =SUM(K9:K13) -> 37.751014 | L15: =SUM(L9:L13) -> 2348.1877 | M15: =SUM(M9:M13) -> 1152.6266 | N15: =SUM(N9:N13) -> 139.43461 | O15: =K15/$F15 -> 0.010264006 | P15: =L15/$F15 -> 0.63844147 | Q15: =M15/$F15 -> 0.31338408 | R15: =N15/$F15 -> 0.037910444
A17: River | B17: Adult Females | C17: Clipped | D17: NA | E17: 2010 | F17: 0
A18: River | B18: Adult Females | C18: Unclipped | D18: Petersen Tagged | E18: 2010 | F18: 648 | G18: 0 | H18: 69 | I18: 93 | J18: 7 | K18: =+(G18/(SUM($G18:$J18)))*$F18 -> 0 | L18: =+(H18/(SUM($G18:$J18)))*$F18 -> 264.56805 | M18: =+(I18/(SUM($G18:$J18)))*$F18 -> 356.59172 | N18: =+(J18/(SUM($G18:$J18)))*$F18 -> 26.840237
A19: River | B19: Adult Females | C19: Unclipped | D19: No Petersen Tag | E19: 2010 | F19: =+F22-SUM(F17:F18) -> 3164 | G19: 0 | H19: 54 | I19: 75 | J19: 8 | K19: =+(G19/(SUM($G19:$J19)))*$F19 -> 0 | L19: =+(H19/(SUM($G19:$J19)))*$F19 -> 1247.1241 | M19: =+(I19/(SUM($G19:$J19)))*$F19 -> 1732.1168 | N19: =+(J19/(SUM($G19:$J19)))*$F19 -> 184.75912
A20: Hatchery | B20: Adult Females | C20: Clipped | D20: No Petersen Tag | E20: 2010 | K20: =+IF($F20=0,0,(G20/(SUM($G20:$J20)))*$F20) -> 0 | L20: =+IF($F20=0,0,(H20/(SUM($G20:$J20)))*$F20) -> 0 | M20: =+IF($F20=0,0,(I20/(SUM($G20:$J20)))*$F20) -> 0 | N20: =+IF($F20=0,0,(J20/(SUM($G20:$J20)))*$F20) -> 0
A21: Hatchery | B21: Adult Females | C21: Unclipped | D21: No Petersen Tag | E21: 2010 | K21: =+IF(G21="",(G19/(SUM($G19:$J19)))*$F21,(G21/(SUM($G21:$J21)))*$F21) -> 0 | L21: =+IF(H21="",(H19/(SUM($G19:$J19)))*$F21,(H21/(SUM($G21:$J21)))*$F21) -> 0 | M21: =+IF(I21="",(I19/(SUM($G19:$J19)))*$F21,(I21/(SUM($G21:$J21)))*$F21) -> 0 | N21: =+IF(J21="",(J19/(SUM($G19:$J19)))*$F21,(J21/(SUM($G21:$J21)))*$F21) -> 0
A22: River | B22: Adult Females | C22: both | D22: both | E22: 2010 | F22: 3812 | K22: =+SUM(K17:K19) -> 0 | L22: =+SUM(L17:L19) -> 1511.6921 | M22: =+SUM(M17:M19) -> 2088.7085 | N22: =+SUM(N17:N19) -> 211.59936 | O22: =K22/$F22 -> 0 | P22: =L22/$F22 -> 0.39656142 | Q22: =M22/$F22 -> 0.54792983 | R22: =N22/$F22 -> 0.055508752
A23: River and Hatchery | B23: Adult Females | C23: both | D23: both | E23: 2010 | F23: =F22+SUM(F20:F21) -> 3812 | K23: =SUM(K17:K21) -> 0 | L23: =SUM(L17:L21) -> 1511.6921 | M23: =SUM(M17:M21) -> 2088.7085 | N23: =SUM(N17:N21) -> 211.59936 | O23: =K23/$F23 -> 0 | P23: =L23/$F23 -> 0.39656142 | Q23: =M23/$F23 -> 0.54792983 | R23: =N23/$F23 -> 0.055508752
A25: River | B25: Jacks | C25: Clipped | D25: NA | E25: 2010 | F25: 0
A26: River | B26: Jacks | C26: Unclipped | D26: Petersen Tagged | E26: 2010 | F26: 14 | G26: 0 | H26: 1 | I26: 0 | J26: 0 | K26: =+(G26/(SUM($G26:$J26)))*$F26 -> 0 | L26: =+(H26/(SUM($G26:$J26)))*$F26 -> 14 | M26: =+(I26/(SUM($G26:$J26)))*$F26 -> 0 | N26: =+(J26/(SUM($G26:$J26)))*$F26 -> 0
A27: River | B27: Jacks | C27: Unclipped | D27: No Petersen Tag | E27: 2010 | F27: =+F30-SUM(F25:F26) -> 14 | G27: 1 | H27: 1 | I27: 0 | J27: 0 | K27: =+(G27/(SUM($G27:$J27)))*$F27 -> 7 | L27: =+(H27/(SUM($G27:$J27)))*$F27 -> 7 | M27: =+(I27/(SUM($G27:$J27)))*$F27 -> 0 | N27: =+(J27/(SUM($G27:$J27)))*$F27 -> 0
A28: Hatchery | B28: Jacks | C28: Clipped | D28: No Petersen Tag | E28: 2010 | K28: =+IF($F28=0,0,(G28/(SUM($G28:$J28)))*$F28) -> 0 | L28: =+IF($F28=0,0,(H28/(SUM($G28:$J28)))*$F28) -> 0 | M28: =+IF($F28=0,0,(I28/(SUM($G28:$J28)))*$F28) -> 0 | N28: =+IF($F28=0,0,(J28/(SUM($G28:$J28)))*$F28) -> 0
A29: Hatchery | B29: Jacks | C29: Unclipped | D29: No Petersen Tag | E29: 2010 | K29: =+IF(G29="",(G27/(SUM($G27:$J27)))*$F29,(G29/(SUM($G29:$J29)))*$F29) -> 0 | L29: =+IF(H29="",(H27/(SUM($G27:$J27)))*$F29,(H29/(SUM($G29:$J29)))*$F29) -> 0 | M29: =+IF(I29="",(I27/(SUM($G27:$J27)))*$F29,(I29/(SUM($G29:$J29)))*$F29) -> 0 | N29: =+IF(J29="",(J27/(SUM($G27:$J27)))*$F29,(J29/(SUM($G29:$J29)))*$F29) -> 0
A30: River | B30: Jacks | C30: both | D30: both | E30: 2010 | F30: 28 | K30: =+SUM(K25:K27) -> 7 | L30: =+SUM(L25:L27) -> 21 | M30: =+SUM(M25:M27) -> 0 | N30: =+SUM(N25:N27) -> 0 | O30: =K30/$F30 -> 0.25 | P30: =L30/$F30 -> 0.75 | Q30: =M30/$F30 -> 0 | R30: =N30/$F30 -> 0
A31: River and Hatchery | B31: Jacks | C31: both | D31: both | E31: 2010 | F31: =F30+SUM(F28:F29) -> 28 | K31: =SUM(K25:K29) -> 7 | L31: =SUM(L25:L29) -> 21 | M31: =SUM(M25:M29) -> 0 | N31: =SUM(N25:N29) -> 0 | O31: =K31/$F31 -> 0.25 | P31: =L31/$F31 -> 0.75 | Q31: =M31/$F31 -> 0 | R31: =N31/$F31 -> 0
A33: River | B33: Adult Males | C33: Clipped | D33: NA | E33: 2011 | F33: 0 | G33: 0 | H33: 0 | I33: 0 | J33: 0
A34: River | B34: Adult Males | C34: Unclipped | D34: Petersen Tagged | E34: 2011 | F34: 265 | G34: 0 | H34: 32 | I34: 66 | J34: 1 | K34: =+(G34/(SUM($G34:$J34)))*$F34 -> 0 | L34: =+(H34/(SUM($G34:$J34)))*$F34 -> 85.656566 | M34: =+(I34/(SUM($G34:$J34)))*$F34 -> 176.66667 | N34: =+(J34/(SUM($G34:$J34)))*$F34 -> 2.6767677
A35: River | B35: Adult Males | C35: Unclipped | D35: No Petersen Tag | E35: 2011 | F35: =+F38-SUM(F33:F34) -> 3250 | G35: 0 | H35: 39 | I35: 127 | J35: 5 | K35: =+(G35/(SUM($G35:$J35)))*$F35 -> 0 | L35: =+(H35/(SUM($G35:$J35)))*$F35 -> 741.22807 | M35: =+(I35/(SUM($G35:$J35)))*$F35 -> 2413.7427 | N35: =+(J35/(SUM($G35:$J35)))*$F35 -> 95.02924
A36: Hatchery | B36: Adult Males | C36: Clipped | D36: No Petersen Tag | E36: 2011 | K36: =+IF($F36=0,0,(G36/(SUM($G36:$J36)))*$F36) -> 0 | L36: =+IF($F36=0,0,(H36/(SUM($G36:$J36)))*$F36) -> 0 | M36: =+IF($F36=0,0,(I36/(SUM($G36:$J36)))*$F36) -> 0 | N36: =+IF($F36=0,0,(J36/(SUM($G36:$J36)))*$F36) -> 0
A37: Hatchery | B37: Adult Males | C37: Unclipped | D37: No Petersen Tag | E37: 2011 | K37: =+IF(G37="",(G35/(SUM($G35:$J35)))*$F37,(G37/(SUM($G37:$J37)))*$F37) -> 0 | L37: =+IF(H37="",(H35/(SUM($G35:$J35)))*$F37,(H37/(SUM($G37:$J37)))*$F37) -> 0 | M37: =+IF(I37="",(I35/(SUM($G35:$J35)))*$F37,(I37/(SUM($G37:$J37)))*$F37) -> 0 | N37: =+IF(J37="",(J35/(SUM($G35:$J35)))*$F37,(J37/(SUM($G37:$J37)))*$F37) -> 0
A38: River | B38: Adult Males | C38: both | D38: both | E38: 2011 | F38: 3515 | K38: =+SUM(K33:K35) -> 0 | L38: =+SUM(L33:L35) -> 826.88464 | M38: =+SUM(M33:M35) -> 2590.4094 | N38: =+SUM(N33:N35) -> 97.706007 | O38: =K38/$F38 -> 0 | P38: =L38/$F38 -> 0.23524456 | Q38: =M38/$F38 -> 0.73695857 | R38: =N38/$F38 -> 0.027796873
A39: River and Hatchery | B39: Adult Males | C39: both | D39: both | E39: 2011 | F39: =F38+SUM(F36:F37) -> 3515 | K39: =SUM(K33:K37) -> 0 | L39: =SUM(L33:L37) -> 826.88464 | M39: =SUM(M33:M37) -> 2590.4094 | N39: =SUM(N33:N37) -> 97.706007 | O39: =K39/$F39 -> 0 | P39: =L39/$F39 -> 0.23524456 | Q39: =M39/$F39 -> 0.73695857 | R39: =N39/$F39 -> 0.027796873
A41: River | B41: Adult Females | C41: Clipped | D41: NA | E41: 2011 | F41: 0
A42: River | B42: Adult Females | C42: Unclipped | D42: Petersen Tagged | E42: 2011 | F42: 466 | G42: 0 | H42: 31 | I42: 158 | J42: 1 | K42: =+(G42/(SUM($G42:$J42)))*$F42 -> 0 | L42: =+(H42/(SUM($G42:$J42)))*$F42 -> 76.031579 | M42: =+(I42/(SUM($G42:$J42)))*$F42 -> 387.51579 | N42: =+(J42/(SUM($G42:$J42)))*$F42 -> 2.4526316
A43: River | B43: Adult Females | C43: Unclipped | D43: No Petersen Tag | E43: 2011 | F43: =+F46-SUM(F41:F42) -> 4415 | G43: 0 | H43: 38 | I43: 290 | J43: 6 | K43: =+(G43/(SUM($G43:$J43)))*$F43 -> 0 | L43: =+(H43/(SUM($G43:$J43)))*$F43 -> 502.30539 | M43: =+(I43/(SUM($G43:$J43)))*$F43 -> 3833.3832 | N43: =+(J43/(SUM($G43:$J43)))*$F43 -> 79.311377
A44: Hatchery | B44: Adult Females | C44: Clipped | D44: No Petersen Tag | E44: 2011 | K44: =+IF($F44=0,0,(G44/(SUM($G44:$J44)))*$F44) -> 0 | L44: =+IF($F44=0,0,(H44/(SUM($G44:$J44)))*$F44) -> 0 | M44: =+IF($F44=0,0,(I44/(SUM($G44:$J44)))*$F44) -> 0 | N44: =+IF($F44=0,0,(J44/(SUM($G44:$J44)))*$F44) -> 0
A45: Hatchery | B45: Adult Females | C45: Unclipped | D45: No Petersen Tag | E45: 2011 | K45: =+IF(G45="",(G43/(SUM($G43:$J43)))*$F45,(G45/(SUM($G45:$J45)))*$F45) -> 0 | L45: =+IF(H45="",(H43/(SUM($G43:$J43)))*$F45,(H45/(SUM($G45:$J45)))*$F45) -> 0 | M45: =+IF(I45="",(I43/(SUM($G43:$J43)))*$F45,(I45/(SUM($G45:$J45)))*$F45) -> 0 | N45: =+IF(J45="",(J43/(SUM($G43:$J43)))*$F45,(J45/(SUM($G45:$J45)))*$F45) -> 0
...

Sheet Corrected Esc by age
A1: This pivot table needs to be updated each year and then the year and age needs to be entered and the formulas extended.
A2: This is where the corrections to the scale ages occur for the unmarked fish.
A3: Do a manual check of totals. Colum J total for the year should equal the combined M,F,J River&Hathcery totals (shaded blue) in Esc&Age data sheet.
B4: Column Labels | D4: year | E4: age | F4: brood year | G4: unique | H4: uncorrected | I4: Corrected_Unclipped | J4: Corrected_unclipped &clipped | K4: Clipped | L4: Uncorrected unclipped and clipped for pre-CWT years
A5: Year | B5: Clipped | C5: Unclipped | D5: year | E5: age | F5: brood year | G5: identifier | H5: unclipped fish | I5: Unclipped Fish | J5: Total | L5: Total.pre CWT
A6: 2010
A7: Sum of Raw_ESC_Age-3 | B7: 0 | C7: 44.751014 | D7: 2010 | E7: 3 | F7: =D7-E7 -> 2007 | G7: =CONCATENATE(D7,".",E7) -> 2010.3 | H7: =C7 -> 44.751014 | I7: =+VLOOKUP(G7,'Scale-CWT correction factors'!J$4:L$333,3,FALSE) -> 0 | J7: =I7+B7 -> 0 | K7: =+B7 -> 0 | L7: =H7+B7 -> 44.751014
A8: Sum of Raw_ESC_Age-4 | B8: 0 | C8: 3880.8799 | D8: 2010 | E8: 4 | F8: =D8-E8 -> 2006 | G8: =CONCATENATE(D8,".",E8) -> 2010.4 | H8: =C8 -> 3880.8799 | I8: =+VLOOKUP(G8,'Scale-CWT correction factors'!J$4:L$333,3,FALSE) -> 0 | J8: =I8+B8 -> 0 | K8: =+B8 -> 0 | L8: =H8+B8 -> 3880.8799
A9: Sum of Raw_ESC_Age-5 | B9: 0 | C9: 3241.3351 | D9: 2010 | E9: 5 | F9: =D9-E9 -> 2005 | G9: =CONCATENATE(D9,".",E9) -> 2010.5 | H9: =C9 -> 3241.3351 | I9: =+VLOOKUP(G9,'Scale-CWT correction factors'!J$4:L$333,3,FALSE) -> 0 | J9: =I9+B9 -> 0 | K9: =+B9 -> 0 | L9: =H9+B9 -> 3241.3351
A10: Sum of Raw_ESC_Age-6 | B10: 0 | C10: 351.03397 | D10: 2010 | E10: 6 | F10: =D10-E10 -> 2004 | G10: =CONCATENATE(D10,".",E10) -> 2010.6 | H10: =C10 -> 351.03397 | I10: =+VLOOKUP(G10,'Scale-CWT correction factors'!J$4:L$333,3,FALSE) -> 0 | J10: =I10+B10 -> 0 | K10: =+B10 -> 0 | L10: =H10+B10 -> 351.03397
A11: 2011
A12: Sum of Raw_ESC_Age-3 | B12: 0 | C12: 19 | D12: 2011 | E12: 3 | F12: =D12-E12 -> 2008 | G12: =CONCATENATE(D12,".",E12) -> 2011.3 | H12: =C12 -> 19 | I12: =+VLOOKUP(G12,'Scale-CWT correction factors'!J$4:L$333,3,FALSE) -> 0 | J12: =I12+B12 -> 0 | K12: =+B12 -> 0 | L12: =H12+B12 -> 19
A13: Sum of Raw_ESC_Age-4 | B13: 0 | C13: 1405.2216 | D13: 2011 | E13: 4 | F13: =D13-E13 -> 2007 | G13: =CONCATENATE(D13,".",E13) -> 2011.4 | H13: =C13 -> 1405.2216 | I13: =+VLOOKUP(G13,'Scale-CWT correction factors'!J$4:L$333,3,FALSE) -> 0 | J13: =I13+B13 -> 0 | K13: =+B13 -> 0 | L13: =H13+B13 -> 1405.2216
A14: Sum of Raw_ESC_Age-5 | B14: 0 | C14: 6811.3084 | D14: 2011 | E14: 5 | F14: =D14-E14 -> 2006 | G14: =CONCATENATE(D14,".",E14) -> 2011.5 | H14: =C14 -> 6811.3084 | I14: =+VLOOKUP(G14,'Scale-CWT correction factors'!J$4:L$333,3,FALSE) -> 0 | J14: =I14+B14 -> 0 | K14: =+B14 -> 0 | L14: =H14+B14 -> 6811.3084
A15: Sum of Raw_ESC_Age-6 | B15: 0 | C15: 179.47002 | D15: 2011 | E15: 6 | F15: =D15-E15 -> 2005 | G15: =CONCATENATE(D15,".",E15) -> 2011.6 | H15: =C15 -> 179.47002 | I15: =+VLOOKUP(G15,'Scale-CWT correction factors'!J$4:L$333,3,FALSE) -> 0 | J15: =I15+B15 -> 0 | K15: =+B15 -> 0 | L15: =H15+B15 -> 179.47002
A16: 2012
A17: Sum of Raw_ESC_Age-3 | B17: 0 | C17: 176.92207 | D17: 2012 | E17: 3 | F17: =D17-E17 -> 2009 | G17: =CONCATENATE(D17,".",E17) -> 2012.3 | H17: =C17 -> 176.92207 | I17: =+VLOOKUP(G17,'Scale-CWT correction factors'!J$4:L$333,3,FALSE) -> 0 | J17: =I17+B17 -> 0 | K17: =+B17 -> 0 | L17: =H17+B17 -> 176.92207
A18: Sum of Raw_ESC_Age-4 | B18: 0 | C18: 1411.3555 | D18: 2012 | E18: 4 | F18: =D18-E18 -> 2008 | G18: =CONCATENATE(D18,".",E18) -> 2012.4 | H18: =C18 -> 1411.3555 | I18: =+VLOOKUP(G18,'Scale-CWT correction factors'!J$4:L$333,3,FALSE) -> 0 | J18: =I18+B18 -> 0 | K18: =+B18 -> 0 | L18: =H18+B18 -> 1411.3555
A19: Sum of Raw_ESC_Age-5 | B19: 0 | C19: 2626.4035 | D19: 2012 | E19: 5 | F19: =D19-E19 -> 2007 | G19: =CONCATENATE(D19,".",E19) -> 2012.5 | H19: =C19 -> 2626.4035 | I19: =+VLOOKUP(G19,'Scale-CWT correction factors'!J$4:L$333,3,FALSE) -> 0 | J19: =I19+B19 -> 0 | K19: =+B19 -> 0 | L19: =H19+B19 -> 2626.4035
A20: Sum of Raw_ESC_Age-6 | B20: 0 | C20: 72.318953 | D20: 2012 | E20: 6 | F20: =D20-E20 -> 2006 | G20: =CONCATENATE(D20,".",E20) -> 2012.6 | H20: =C20 -> 72.318953 | I20: =+VLOOKUP(G20,'Scale-CWT correction factors'!J$4:L$333,3,FALSE) -> 0 | J20: =I20+B20 -> 0 | K20: =+B20 -> 0 | L20: =H20+B20 -> 72.318953
A21: 2013
A22: Sum of Raw_ESC_Age-3 | B22: 0 | C22: 400.7559 | D22: 2013 | E22: 3 | F22: =D22-E22 -> 2010 | G22: =CONCATENATE(D22,".",E22) -> 2013.3 | H22: =C22 -> 400.7559 | I22: =+VLOOKUP(G22,'Scale-CWT correction factors'!J$4:L$333,3,FALSE) -> 0 | J22: =I22+B22 -> 0 | K22: =+B22 -> 0 | L22: =H22+B22 -> 400.7559
A23: Sum of Raw_ESC_Age-4 | B23: 0 | C23: 2495.8152 | D23: 2013 | E23: 4 | F23: =D23-E23 -> 2009 | G23: =CONCATENATE(D23,".",E23) -> 2013.4 | H23: =C23 -> 2495.8152 | I23: =+VLOOKUP(G23,'Scale-CWT correction factors'!J$4:L$333,3,FALSE) -> 0 | J23: =I23+B23 -> 0 | K23: =+B23 -> 0 | L23: =H23+B23 -> 2495.8152
A24: Sum of Raw_ESC_Age-5 | B24: 0 | C24: 1486.2445 | D24: 2013 | E24: 5 | F24: =D24-E24 -> 2008 | G24: =CONCATENATE(D24,".",E24) -> 2013.5 | H24: =C24 -> 1486.2445 | I24: =+VLOOKUP(G24,'Scale-CWT correction factors'!J$4:L$333,3,FALSE) -> 0 | J24: =I24+B24 -> 0 | K24: =+B24 -> 0 | L24: =H24+B24 -> 1486.2445
A25: Sum of Raw_ESC_Age-6 | B25: 0 | C25: 40.184392 | D25: 2013 | E25: 6 | F25: =D25-E25 -> 2007 | G25: =CONCATENATE(D25,".",E25) -> 2013.6 | H25: =C25 -> 40.184392 | I25: =+VLOOKUP(G25,'Scale-CWT correction factors'!J$4:L$333,3,FALSE) -> 0 | J25: =I25+B25 -> 0 | K25: =+B25 -> 0 | L25: =H25+B25 -> 40.184392
A26: 2014
A27: Sum of Raw_ESC_Age-3 | B27: 0 | C27: 30.842105 | D27: 2014 | E27: 3 | F27: =D27-E27 -> 2011 | G27: =CONCATENATE(D27,".",E27) -> 2014.3 | H27: =C27 -> 30.842105 | I27: =+VLOOKUP(G27,'Scale-CWT correction factors'!J$4:L$333,3,FALSE) -> 0 | J27: =I27+B27 -> 0 | K27: =+B27 -> 0 | L27: =H27+B27 -> 30.842105
A28: Sum of Raw_ESC_Age-4 | B28: 0 | C28: 5816.2648 | D28: 2014 | E28: 4 | F28: =D28-E28 -> 2010 | G28: =CONCATENATE(D28,".",E28) -> 2014.4 | H28: =C28 -> 5816.2648 | I28: =+VLOOKUP(G28,'Scale-CWT correction factors'!J$4:L$333,3,FALSE) -> 0 | J28: =I28+B28 -> 0 | K28: =+B28 -> 0 | L28: =H28+B28 -> 5816.2648
A29: Sum of Raw_ESC_Age-5 | B29: 0 | C29: 7388.9483 | D29: 2014 | E29: 5 | F29: =D29-E29 -> 2009 | G29: =CONCATENATE(D29,".",E29) -> 2014.5 | H29: =C29 -> 7388.9483 | I29: =+VLOOKUP(G29,'Scale-CWT correction factors'!J$4:L$333,3,FALSE) -> 0 | J29: =I29+B29 -> 0 | K29: =+B29 -> 0 | L29: =H29+B29 -> 7388.9483
A30: Sum of Raw_ESC_Age-6 | B30: 0 | C30: 129.94476 | D30: 2014 | E30: 6 | F30: =D30-E30 -> 2008 | G30: =CONCATENATE(D30,".",E30) -> 2014.6 | H30: =C30 -> 129.94476 | I30: =+VLOOKUP(G30,'Scale-CWT correction factors'!J$4:L$333,3,FALSE) -> 0 | J30: =I30+B30 -> 0 | K30: =+B30 -> 0 | L30: =H30+B30 -> 129.94476
A31: 2015
A32: Sum of Raw_ESC_Age-3 | B32: 0 | C32: 19.136842 | D32: 2015 | E32: 3 | F32: =D32-E32 -> 2012 | G32: =CONCATENATE(D32,".",E32) -> 2015.3 | H32: =C32 -> 19.136842 | I32: =+VLOOKUP(G32,'Scale-CWT correction factors'!J$4:L$333,3,FALSE) -> 0 | J32: =I32+B32 -> 0 | K32: =+B32 -> 0 | L32: =H32+B32 -> 19.136842
A33: Sum of Raw_ESC_Age-4 | B33: 0 | C33: 3350.261 | D33: 2015 | E33: 4 | F33: =D33-E33 -> 2011 | G33: =CONCATENATE(D33,".",E33) -> 2015.4 | H33: =C33 -> 3350.261 | I33: =+VLOOKUP(G33,'Scale-CWT correction factors'!J$4:L$333,3,FALSE) -> 0 | J33: =I33+B33 -> 0 | K33: =+B33 -> 0 | L33: =H33+B33 -> 3350.261
A34: Sum of Raw_ESC_Age-5 | B34: 0 | C34: 7530.9115 | D34: 2015 | E34: 5 | F34: =D34-E34 -> 2010 | G34: =CONCATENATE(D34,".",E34) -> 2015.5 | H34: =C34 -> 7530.9115 | I34: =+VLOOKUP(G34,'Scale-CWT correction factors'!J$4:L$333,3,FALSE) -> 0 | J34: =I34+B34 -> 0 | K34: =+B34 -> 0 | L34: =H34+B34 -> 7530.9115
A35: Sum of Raw_ESC_Age-6 | B35: 0 | C35: 97.690702 | D35: 2015 | E35: 6 | F35: =D35-E35 -> 2009 | G35: =CONCATENATE(D35,".",E35) -> 2015.6 | H35: =C35 -> 97.690702 | I35: =+VLOOKUP(G35,'Scale-CWT correction factors'!J$4:L$333,3,FALSE) -> 0 | J35: =I35+B35 -> 0 | K35: =+B35 -> 0 | L35: =H35+B35 -> 97.690702
A36: 2016
A37: Sum of Raw_ESC_Age-3 | B37: 0 | C37: 109 | D37: 2016 | E37: 3 | F37: =D37-E37 -> 2013 | G37: =CONCATENATE(D37,".",E37) -> 2016.3 | H37: =C37 -> 109 | I37: =+VLOOKUP(G37,'Scale-CWT correction factors'!J$4:L$333,3,FALSE) -> 0 | J37: =I37+B37 -> 0 | K37: =+B37 -> 0 | L37: =H37+B37 -> 109
A38: Sum of Raw_ESC_Age-4 | B38: 0 | C38: 1251.3861 | D38: 2016 | E38: 4 | F38: =D38-E38 -> 2012 | G38: =CONCATENATE(D38,".",E38) -> 2016.4 | H38: =C38 -> 1251.3861 | I38: =+VLOOKUP(G38,'Scale-CWT correction factors'!J$4:L$333,3,FALSE) -> 0 | J38: =I38+B38 -> 0 | K38: =+B38 -> 0 | L38: =H38+B38 -> 1251.3861
A39: Sum of Raw_ESC_Age-5 | B39: 0 | C39: 2613.9069 | D39: 2016 | E39: 5 | F39: =D39-E39 -> 2011 | G39: =CONCATENATE(D39,".",E39) -> 2016.5 | H39: =C39 -> 2613.9069 | I39: =+VLOOKUP(G39,'Scale-CWT correction factors'!J$4:L$333,3,FALSE) -> 0 | J39: =I39+B39 -> 0 | K39: =+B39 -> 0 | L39: =H39+B39 -> 2613.9069
A40: Sum of Raw_ESC_Age-6 | B40: 0 | C40: 308.707 | D40: 2016 | E40: 6 | F40: =D40-E40 -> 2010 | G40: =CONCATENATE(D40,".",E40) -> 2016.6 | H40: =C40 -> 308.707 | I40: =+VLOOKUP(G40,'Scale-CWT correction factors'!J$4:L$333,3,FALSE) -> 0 | J40: =I40+B40 -> 0 | K40: =+B40 -> 0 | L40: =H40+B40 -> 308.707
...

Sheet Esc Age for Study Design
M3: OLD
M5: year | N5: age | O5: Total | P5: Percent of Return | Q5: Unknown Column???
M6: 2010 | N6: 3 | O6: 44.751014 | P6: =O6/SUM(O$6:$O$9) -> 0.0059525159
A7: Sum of Corrected_Unclipped | B7: Column Labels | M7: 2010 | N7: 4 | O7: 3880.8799 | P7: =O7/SUM(O$6:$O$9) -> 0.51621174
A8: Row Labels | B8: 3 | C8: 4 | D8: 5 | E8: 6 | F8: Grand Total | G8: Year | H8: % Esc age 3 (Jack) | I8: % Esc age 4 | J8: % Esc age 5 | K8: % Esc age 6 | M8: 2010 | N8: 5 | O8: 3241.3351 | P8: =O8/SUM(O$6:$O$9) -> 0.43114328
A9: 2017 | B9: 3426.4286 | C9: 263.57143 | D9: 0 | E9: 0 | F9: 3690 | G9: =A11 -> 2019 | H9: =B11/$F11 -> 0 | I9: =C11/$F11 -> 0.42926829 | J9: =D11/$F11 -> 0.57073171 | K9: =E11/$F11 -> 0 | M9: 2010 | N9: 6 | O9: 351.03397 | P9: =O9/SUM(O$6:$O$9) -> 0.046692468
A10: 2018 | B10: 0 | C10: 1186.3231 | D10: 1031.6769 | E10: 0 | F10: 2218 | G10: =A12 -> 2020 | H10: =B12/$F12 -> 0.021732183 | I10: =C12/$F12 -> 0.28724722 | J10: =D12/$F12 -> 0.6910206 | K10: =E12/$F12 -> 0
A11: 2019 | B11: 0 | C11: 1027.239 | D11: 1365.761 | E11: 0 | F11: 2393 | G11: =A13 -> 2021 | H11: =B13/$F13 -> 0.031759786 | I11: =C13/$F13 -> 0.5948688 | J11: =D13/$F13 -> 0.37337142 | K11: =E13/$F13 -> 0 | M11: 2011 | N11: 3 | O11: 19 | P11: =O11/SUM(O$11:$O$14) -> 0.0022578728
A12: 2020 | B12: 136 | C12: 1797.5931 | D12: 4324.4069 | E12: 0 | F12: 6258 | G12: 2022 | H12: =B14/$F14 -> 0 | I12: =C14/$F14 -> 0.3825522 | J12: =D14/$F14 -> 0.6174478 | K12: =E14/$F14 -> 0 | M12: 2011 | N12: 4 | O12: 1405.2216 | P12: =O12/SUM(O$11:$O$14) -> 0.16699009
A13: 2021 | B13: 165.81785 | C13: 3105.81 | D13: 1949.3722 | E13: 0 | F13: 5221 | G13: 2023 | H13: =B15/$F15 -> 0.03252278 | I13: =C15/$F15 -> 0.34679649 | J13: =D15/$F15 -> 0.62068073 | K13: =E15/$F15 -> 0 | M13: 2011 | N13: 5 | O13: 6811.3084 | P13: =O13/SUM(O$11:$O$14) -> 0.80942464
A14: 2022 | B14: 0 | C14: 4971.6484 | D14: 8024.3516 | E14: 0 | F14: 12996 | G14: 2024 | H14: =B16/$F16 -> 0.049863175 | I14: =C16/$F16 -> 0.76481045 | J14: =D16/$F16 -> 0.18532638 | K14: =E16/$F16 -> 0 | M14: 2011 | N14: 6 | O14: 179.47002 | P14: =O14/SUM(O$11:$O$14) -> 0.021327393
A15: 2023 | B15: 233.54608 | C15: 2490.3456 | D15: 4457.1083 | E15: 0 | F15: 7181 | G15: 6 Yr Average | H15: =AVERAGE(H9:H13) -> 0.01720295 | I15: =AVERAGE(I9:I13) -> 0.4081466 | J15: =AVERAGE(J9:J13) -> 0.57465045 | K15: =AVERAGE(K9:K13) -> 0
A16: 2024 | B16: 214.16234 | C16: 3284.8609 | D16: 795.97679 | E16: 0 | F16: 4295 | M16: 2012 | N16: 3 | O16: 176.92207 | P16: =O16/SUM(O$16:$O$19) -> 0.041269436
A17: Grand Total | B17: 4175.9548 | C17: 18127.392 | D17: 21948.654 | E17: 0 | F17: 44252 | M17: 2012 | N17: 4 | O17: 1411.3555 | P17: =O17/SUM(O$16:$O$19) -> 0.32921751
M18: 2012 | N18: 5 | O18: 2626.4035 | P18: =O18/SUM(O$16:$O$19) -> 0.61264369
M19: 2012 | N19: 6 | O19: 72.318953 | P19: =O19/SUM(O$16:$O$19) -> 0.016869362
M21: 2013 | N21: 3 | O21: 400.7559 | P21: =O21/SUM(O$21:$O$24) -> 0.090607259
M22: 2013 | N22: 4 | O22: 2495.8152 | P22: =O22/SUM(O$21:$O$24) -> 0.56428109
M23: 2013 | N23: 5 | O23: 1486.2445 | P23: =O23/SUM(O$21:$O$24) -> 0.33602633
M24: 2013 | N24: 6 | O24: 40.184392 | P24: =O24/SUM(O$21:$O$24) -> 0.009085325
M26: 2014 | N26: 3 | O26: 30.842105 | P26: =O26/SUM(O$26:$O$29) -> 0.0023075045
M27: 2014 | N27: 4 | O27: 5816.2648 | P27: =O27/SUM(O$26:$O$29) -> 0.43515374
M28: 2014 | N28: 5 | O28: 7388.9483 | P28: =O28/SUM(O$26:$O$29) -> 0.55281672
M29: 2014 | N29: 6 | O29: 129.94476 | P29: =O29/SUM(O$26:$O$29) -> 0.0097220383
M31: 2015 | N31: 3 | O31: 19.136842 | P31: =O31/SUM(O$31:$O$34) -> 0.0017400293
M32: 2015 | N32: 4 | O32: 3350.261 | P32: =O32/SUM(O$31:$O$34) -> 0.30462457
M33: 2015 | N33: 5 | O33: 7530.9115 | P33: =O33/SUM(O$31:$O$34) -> 0.68475282
M34: 2015 | N34: 6 | O34: 97.690702 | P34: =O34/SUM(O$31:$O$34) -> 0.0088825879
M36: 2016 | N36: 3 | O36: 109 | P36: =O36/SUM(O$36:$O$39) -> 0.025449451
M37: 2016 | N37: 4 | O37: 1251.3861 | P37: =O37/SUM(O$36:$O$39) -> 0.29217514
M38: 2016 | N38: 5 | O38: 2613.9069 | P38: =O38/SUM(O$36:$O$39) -> 0.61029813
M39: 2016 | N39: 6 | O39: 308.707 | P39: =O39/SUM(O$36:$O$39) -> 0.072077282
M41: 2017 | N41: 3 | O41: 9.5 | P41: =O41/SUM(O$41:$O$44) -> 0.0025689562 | Q41: 0.125
M42: 2017 | N42: 4 | O42: 1542.2316 | P42: =O42/SUM(O$41:$O$44) -> 0.41704479 | Q42: 0.27313866
M43: 2017 | N43: 5 | O43: 1944.928 | P43: =O43/SUM(O$41:$O$44) -> 0.5259405 | Q43: 0.55245902
M44: 2017 | N44: 6 | O44: 201.3404 | P44: =O44/SUM(O$41:$O$44) -> 0.054445754 | Q44: 0.049402322
M46: 2018 | N46: 3 | O46: 0 | P46: =O46/SUM(O$46:$O$49) -> 0 | Q46: 0
M47: 2018 | N47: 4 | O47: 1203.4591 | P47: =O47/SUM(O$46:$O$49) -> 0.52415467 | Q47: 0.52415467
M48: 2018 | N48: 5 | O48: 1049.9035 | P48: =O48/SUM(O$46:$O$49) -> 0.45727506 | Q48: 0.45727506
M49: 2018 | N49: 6 | O49: 42.637323 | P49: =O49/SUM(O$46:$O$49) -> 0.018570263 | Q49: 0.018570263
...

Sheet Scale-CWT correction factors
A1: Only fish with paired scales and CWTs to estimate correction factors | L1: UNCLIPPED | N1: See next tab for corrected esc by age
D2: cwt age | K2: UNCLIPPED | L2: Corrected | M2: corrected ages
A3: River | B3: Year | C3: scale age | D3: 2 | E3: 3 | F3: 4 | G3: 5 | H3: 6 | I3: Total | J3: Identified | K3: Uncorrected ages | M3: 3 | N3: 4 | O3: 5 | P3: 6 | Q3: checks
A4: Chilko | B4: 2010 | C4: 3 | I4: =SUM(D4:H4) -> 0 | J4: =+CONCATENATE(B4,".",C4) -> 2010.3 | K4: =+VLOOKUP(J4,'Corrected Esc by age'!G$7:H$402,2,FALSE) -> 44.751014 | L4: =+SUM(M4:M7) -> 0
A5: Chilko | B5: 2010 | C5: 4 | I5: =SUM(D5:H5) -> 0 | J5: =+CONCATENATE(B5,".",C5) -> 2010.4 | K5: =+VLOOKUP(J5,'Corrected Esc by age'!G$7:H$402,2,FALSE) -> 3880.8799 | L5: =+SUM(N4:N7) -> 0
A6: Chilko | B6: 2010 | C6: 5 | I6: =SUM(D6:H6) -> 0 | J6: =+CONCATENATE(B6,".",C6) -> 2010.5 | K6: =+VLOOKUP(J6,'Corrected Esc by age'!G$7:H$402,2,FALSE) -> 3241.3351 | L6: =+SUM(O4:O7) -> 0
A7: Chilko | B7: 2010 | C7: 6 | I7: =SUM(D7:H7) -> 0 | J7: =+CONCATENATE(B7,".",C7) -> 2010.6 | K7: =+VLOOKUP(J7,'Corrected Esc by age'!G$7:H$402,2,FALSE) -> 351.03397 | L7: =+SUM(P4:P7) -> 0
A8: Chilko | B8: 2011 | C8: 3 | I8: =SUM(D8:H8) -> 0 | J8: =+CONCATENATE(B8,".",C8) -> 2011.3 | K8: =+VLOOKUP(J8,'Corrected Esc by age'!G$7:H$402,2,FALSE) -> 19 | L8: =+SUM(M8:M11) -> 0
A9: Chilko | B9: 2011 | C9: 4 | I9: =SUM(D9:H9) -> 0 | J9: =+CONCATENATE(B9,".",C9) -> 2011.4 | K9: =+VLOOKUP(J9,'Corrected Esc by age'!G$7:H$402,2,FALSE) -> 1405.2216 | L9: =+SUM(N8:N11) -> 0
A10: Chilko | B10: 2011 | C10: 5 | I10: =SUM(D10:H10) -> 0 | J10: =+CONCATENATE(B10,".",C10) -> 2011.5 | K10: =+VLOOKUP(J10,'Corrected Esc by age'!G$7:H$402,2,FALSE) -> 6811.3084 | L10: =+SUM(O8:O11) -> 0
A11: Chilko | B11: 2011 | C11: 6 | I11: =SUM(D11:H11) -> 0 | J11: =+CONCATENATE(B11,".",C11) -> 2011.6 | K11: =+VLOOKUP(J11,'Corrected Esc by age'!G$7:H$402,2,FALSE) -> 179.47002 | L11: =+SUM(P8:P11) -> 0
A12: Chilko | B12: 2012 | C12: 3 | I12: =SUM(D12:H12) -> 0 | J12: =+CONCATENATE(B12,".",C12) -> 2012.3 | K12: =+VLOOKUP(J12,'Corrected Esc by age'!G$7:H$402,2,FALSE) -> 176.92207 | L12: =+SUM(M12:M15) -> 0 | U12: Row Labels | V12: Sum of 3 | W12: Sum of 4 | X12: Sum of 5 | Y12: Sum of 6
A13: Chilko | B13: 2012 | C13: 4 | I13: =SUM(D13:H13) -> 0 | J13: =+CONCATENATE(B13,".",C13) -> 2012.4 | K13: =+VLOOKUP(J13,'Corrected Esc by age'!G$7:H$402,2,FALSE) -> 1411.3555 | L13: =+SUM(N12:N15) -> 0 | U13: 3 | V13: 13 | W13: 1 | X13: 0 | AA13: =SUM(V13:Z13) -> 14
A14: Chilko | B14: 2012 | C14: 5 | I14: =SUM(D14:H14) -> 0 | J14: =+CONCATENATE(B14,".",C14) -> 2012.5 | K14: =+VLOOKUP(J14,'Corrected Esc by age'!G$7:H$402,2,FALSE) -> 2626.4035 | L14: =+SUM(O12:O15) -> 0 | U14: 4 | V14: 4 | W14: 253 | X14: 12 | AA14: =SUM(V14:Z14) -> 269
A15: Chilko | B15: 2012 | C15: 6 | I15: =SUM(D15:H15) -> 0 | J15: =+CONCATENATE(B15,".",C15) -> 2012.6 | K15: =+VLOOKUP(J15,'Corrected Esc by age'!G$7:H$402,2,FALSE) -> 72.318953 | L15: =+SUM(P12:P15) -> 0 | U15: 5 | V15: 0 | W15: 4 | X15: 65 | AA15: =SUM(V15:Z15) -> 69
A16: Chilko | B16: 2013 | C16: 3 | I16: =SUM(D16:H16) -> 0 | J16: =+CONCATENATE(B16,".",C16) -> 2013.3 | K16: =+VLOOKUP(J16,'Corrected Esc by age'!G$7:H$402,2,FALSE) -> 400.7559 | L16: =+SUM(M16:M19) -> 0 | U16: 6 | V16: 0 | W16: 0 | X16: 3 | AA16: =SUM(V16:Z16) -> 3
A17: Chilko | B17: 2013 | C17: 4 | I17: =SUM(D17:H17) -> 0 | J17: =+CONCATENATE(B17,".",C17) -> 2013.4 | K17: =+VLOOKUP(J17,'Corrected Esc by age'!G$7:H$402,2,FALSE) -> 2495.8152 | L17: =+SUM(N16:N19) -> 0 | U17: (blank)
A18: Chilko | B18: 2013 | C18: 5 | I18: =SUM(D18:H18) -> 0 | J18: =+CONCATENATE(B18,".",C18) -> 2013.5 | K18: =+VLOOKUP(J18,'Corrected Esc by age'!G$7:H$402,2,FALSE) -> 1486.2445 | L18: =+SUM(O16:O19) -> 0 | U18: Grand Total | V18: 17 | W18: 258 | X18: 80
A19: Chilko | B19: 2013 | C19: 6 | I19: =SUM(D19:H19) -> 0 | J19: =+CONCATENATE(B19,".",C19) -> 2013.6 | K19: =+VLOOKUP(J19,'Corrected Esc by age'!G$7:H$402,2,FALSE) -> 40.184392 | L19: =+SUM(P16:P19) -> 0
A20: Chilko | B20: 2014 | C20: 3 | I20: =SUM(D20:H20) -> 0 | J20: =+CONCATENATE(B20,".",C20) -> 2014.3 | K20: =+VLOOKUP(J20,'Corrected Esc by age'!G$7:H$402,2,FALSE) -> 30.842105 | L20: =+SUM(M20:M23) -> 0
A21: Chilko | B21: 2014 | C21: 4 | I21: =SUM(D21:H21) -> 0 | J21: =+CONCATENATE(B21,".",C21) -> 2014.4 | K21: =+VLOOKUP(J21,'Corrected Esc by age'!G$7:H$402,2,FALSE) -> 5816.2648 | L21: =+SUM(N20:N23) -> 0
A22: Chilko | B22: 2014 | C22: 5 | I22: =SUM(D22:H22) -> 0 | J22: =+CONCATENATE(B22,".",C22) -> 2014.5 | K22: =+VLOOKUP(J22,'Corrected Esc by age'!G$7:H$402,2,FALSE) -> 7388.9483 | L22: =+SUM(O20:O23) -> 0
A23: Chilko | B23: 2014 | C23: 6 | I23: =SUM(D23:H23) -> 0 | J23: =+CONCATENATE(B23,".",C23) -> 2014.6 | K23: =+VLOOKUP(J23,'Corrected Esc by age'!G$7:H$402,2,FALSE) -> 129.94476 | L23: =+SUM(P20:P23) -> 0
A24: Chilko | B24: 2015 | C24: 3 | I24: =SUM(D24:H24) -> 0 | J24: =+CONCATENATE(B24,".",C24) -> 2015.3 | K24: =+VLOOKUP(J24,'Corrected Esc by age'!G$7:H$402,2,FALSE) -> 19.136842 | L24: =+SUM(M24:M27) -> 0
A25: Chilko | B25: 2015 | C25: 4 | I25: =SUM(D25:H25) -> 0 | J25: =+CONCATENATE(B25,".",C25) -> 2015.4 | K25: =+VLOOKUP(J25,'Corrected Esc by age'!G$7:H$402,2,FALSE) -> 3350.261 | L25: =+SUM(N24:N27) -> 0
A26: Chilko | B26: 2015 | C26: 5 | I26: =SUM(D26:H26) -> 0 | J26: =+CONCATENATE(B26,".",C26) -> 2015.5 | K26: =+VLOOKUP(J26,'Corrected Esc by age'!G$7:H$402,2,FALSE) -> 7530.9115 | L26: =+SUM(O24:O27) -> 0
A27: Chilko | B27: 2015 | C27: 6 | I27: =SUM(D27:H27) -> 0 | J27: =+CONCATENATE(B27,".",C27) -> 2015.6 | K27: =+VLOOKUP(J27,'Corrected Esc by age'!G$7:H$402,2,FALSE) -> 97.690702 | L27: =+SUM(P24:P27) -> 0
A28: Chilko | B28: 2016 | C28: 3 | I28: =SUM(D28:H28) -> 0 | J28: =+CONCATENATE(B28,".",C28) -> 2016.3 | K28: =+VLOOKUP(J28,'Corrected Esc by age'!G$7:H$402,2,FALSE) -> 109 | L28: =+SUM(M28:M31) -> 0
A29: Chilko | B29: 2016 | C29: 4 | I29: =SUM(D29:H29) -> 0 | J29: =+CONCATENATE(B29,".",C29) -> 2016.4 | K29: =+VLOOKUP(J29,'Corrected Esc by age'!G$7:H$402,2,FALSE) -> 1251.3861 | L29: =+SUM(N28:N31) -> 0
A30: Chilko | B30: 2016 | C30: 5 | I30: =SUM(D30:H30) -> 0 | J30: =+CONCATENATE(B30,".",C30) -> 2016.5 | K30: =+VLOOKUP(J30,'Corrected Esc by age'!G$7:H$402,2,FALSE) -> 2613.9069 | L30: =+SUM(O28:O31) -> 0
A31: Chilko | B31: 2016 | C31: 6 | I31: =SUM(D31:H31) -> 0 | J31: =+CONCATENATE(B31,".",C31) -> 2016.6 | K31: =+VLOOKUP(J31,'Corrected Esc by age'!G$7:H$402,2,FALSE) -> 308.707 | L31: =+SUM(P28:P31) -> 0
A32: Chilko | B32: 2017 | C32: 3 | I32: =SUM(D32:H32) -> 0 | J32: =+CONCATENATE(B32,".",C32) -> 2017.3 | K32: =+VLOOKUP(J32,'Corrected Esc by age'!G$7:H$402,2,FALSE) -> 8.5 | L32: =+SUM(M32:M35) -> 3426.4286 | M32: =+IF((SUM($D32:$H32)=0),(V$13/$AA$13)*$K32,(E32/$I32)*$K32) -> 7.8928571 | N32: =+IF((SUM($D32:$H32)=0),(W$13/$AA$13)*$K32,(F32/$I32)*$K32) -> 0.60714286 | O32: =+IF((SUM($D32:$H32)=0),(X$13/$AA$13)*$K32,(G32/$I32)*$K32) -> 0 | P32: =+IF((SUM($D32:$H32)=0),(Y$13/$AA$13)*$K32,(H32/$I32)*$K32) -> 0
A33: Chilko | B33: 2017 | C33: 4 | I33: =SUM(D33:H33) -> 0 | J33: =+CONCATENATE(B33,".",C33) -> 2017.4 | K33: =+VLOOKUP(J33,'Corrected Esc by age'!G$7:H$402,2,FALSE) -> 1540.0465 | L33: =+SUM(N32:N35) -> 263.57143 | M33: =+IF((SUM($D33:$H33)=0),(V$13/$AA$13)*$K33,(E33/$I33)*$K33) -> 1430.0432 | N33: =+IF((SUM($D33:$H33)=0),(W$13/$AA$13)*$K33,(F33/$I33)*$K33) -> 110.00332 | O33: =+IF((SUM($D33:$H33)=0),(X$13/$AA$13)*$K33,(G33/$I33)*$K33) -> 0 | P33: =+IF((SUM($D33:$H33)=0),(Y$13/$AA$13)*$K33,(H33/$I33)*$K33) -> 0
A34: Chilko | B34: 2017 | C34: 5 | I34: =SUM(D34:H34) -> 0 | J34: =+CONCATENATE(B34,".",C34) -> 2017.5 | K34: =+VLOOKUP(J34,'Corrected Esc by age'!G$7:H$402,2,FALSE) -> 1940.5083 | L34: =+SUM(O32:O35) -> 0 | M34: =+IF((SUM($D34:$H34)=0),(V$13/$AA$13)*$K34,(E34/$I34)*$K34) -> 1801.9006 | N34: =+IF((SUM($D34:$H34)=0),(W$13/$AA$13)*$K34,(F34/$I34)*$K34) -> 138.60774 | O34: =+IF((SUM($D34:$H34)=0),(X$13/$AA$13)*$K34,(G34/$I34)*$K34) -> 0 | P34: =+IF((SUM($D34:$H34)=0),(Y$13/$AA$13)*$K34,(H34/$I34)*$K34) -> 0
A35: Chilko | B35: 2017 | C35: 6 | I35: =SUM(D35:H35) -> 0 | J35: =+CONCATENATE(B35,".",C35) -> 2017.6 | K35: =+VLOOKUP(J35,'Corrected Esc by age'!G$7:H$402,2,FALSE) -> 200.94518 | L35: =+SUM(P32:P35) -> 0 | M35: =+IF((SUM($D35:$H35)=0),(V$13/$AA$13)*$K35,(E35/$I35)*$K35) -> 186.59195 | N35: =+IF((SUM($D35:$H35)=0),(W$13/$AA$13)*$K35,(F35/$I35)*$K35) -> 14.353227 | O35: =+IF((SUM($D35:$H35)=0),(X$13/$AA$13)*$K35,(G35/$I35)*$K35) -> 0 | P35: =+IF((SUM($D35:$H35)=0),(Y$13/$AA$13)*$K35,(H35/$I35)*$K35) -> 0
A36: Chilko | B36: 2018 | C36: 3 | I36: =SUM(D36:H36) -> 0 | J36: =+CONCATENATE(B36,".",C36) -> 2018.3 | K36: =+VLOOKUP(J36,'Corrected Esc by age'!G$7:H$402,2,FALSE) -> 0 | L36: =+SUM(M36:M39) -> 0 | M36: =+IF((SUM($D36:$H36)=0),(V$13/$AA$13)*$K36,(E36/$I36)*$K36) -> 0 | N36: =+IF((SUM($D36:$H36)=0),(W$13/$AA$13)*$K36,(F36/$I36)*$K36) -> 0 | O36: =+IF((SUM($D36:$H36)=0),(X$13/$AA$13)*$K36,(G36/$I36)*$K36) -> 0 | P36: =+IF((SUM($D36:$H36)=0),(Y$13/$AA$13)*$K36,(H36/$I36)*$K36) -> 0
A37: Chilko | B37: 2018 | C37: 4 | F37: 14 | I37: =SUM(D37:H37) -> 14 | J37: =+CONCATENATE(B37,".",C37) -> 2018.4 | K37: =+VLOOKUP(J37,'Corrected Esc by age'!G$7:H$402,2,FALSE) -> 1125.4591 | L37: =+SUM(N36:N39) -> 1186.3231 | M37: =+IF((SUM($D37:$H37)=0),(V$14/$AA$14)*$K37,(E37/$I37)*$K37) -> 0 | N37: =+IF((SUM($D37:$H37)=0),(W$14/$AA$14)*$K37,(F37/$I37)*$K37) -> 1125.4591 | O37: =+IF((SUM($D37:$H37)=0),(X$14/$AA$14)*$K37,(G37/$I37)*$K37) -> 0 | P37: =+IF((SUM($D37:$H37)=0),(Y$14/$AA$14)*$K37,(H37/$I37)*$K37) -> 0
A38: Chilko | B38: 2018 | C38: 5 | I38: =SUM(D38:H38) -> 0 | J38: =+CONCATENATE(B38,".",C38) -> 2018.5 | K38: =+VLOOKUP(J38,'Corrected Esc by age'!G$7:H$402,2,FALSE) -> 1049.9035 | L38: =+SUM(O36:O39) -> 1031.6769 | M38: =+IF((SUM($D38:$H38)=0),(V$15/$AA$15)*$K38,(E38/$I38)*$K38) -> 0 | N38: =+IF((SUM($D38:$H38)=0),(W$15/$AA$15)*$K38,(F38/$I38)*$K38) -> 60.863974 | O38: =+IF((SUM($D38:$H38)=0),(X$15/$AA$15)*$K38,(G38/$I38)*$K38) -> 989.03957 | P38: =+IF((SUM($D38:$H38)=0),(Y$15/$AA$15)*$K38,(H38/$I38)*$K38) -> 0
A39: Chilko | B39: 2018 | C39: 6 | I39: =SUM(D39:H39) -> 0 | J39: =+CONCATENATE(B39,".",C39) -> 2018.6 | K39: =+VLOOKUP(J39,'Corrected Esc by age'!G$7:H$402,2,FALSE) -> 42.637323 | L39: =SUM(P36:P39) -> 0 | M39: =+IF((SUM($D39:$H39)=0),(V$16/$AA$16)*$K39,(E39/$I39)*$K39) -> 0 | N39: =+IF((SUM($D39:$H39)=0),(W$16/$AA$16)*$K39,(F39/$I39)*$K39) -> 0 | O39: =+IF((SUM($D39:$H39)=0),(X$16/$AA$16)*$K39,(G39/$I39)*$K39) -> 42.637323 | P39: =+IF((SUM($D39:$H39)=0),(Y$16/$AA$16)*$K39,(H39/$I39)*$K39) -> 0
A40: Chilko | B40: 2019 | C40: 3 | I40: =SUM(D40:H40) -> 0 | J40: =+CONCATENATE(B40,".",C40) -> 2019.3 | K40: =+VLOOKUP(J40,'Corrected Esc by age'!G$7:H$402,2,FALSE) -> 0 | L40: =+SUM(M40:M43) -> 0 | M40: =+IF((SUM($D40:$H40)=0),(V$13/$AA$13)*$K40,(E40/$I40)*$K40) -> 0 | N40: =+IF((SUM($D40:$H40)=0),(W$13/$AA$13)*$K40,(F40/$I40)*$K40) -> 0 | O40: =+IF((SUM($D40:$H40)=0),(X$13/$AA$13)*$K40,(G40/$I40)*$K40) -> 0 | P40: =+IF((SUM($D40:$H40)=0),(Y$13/$AA$13)*$K40,(H40/$I40)*$K40) -> 0
...

Sheet Age-specific Escapement Sum
A1: Stratum | B1: (Multiple Items)
A2: Location | B2: River and Hatchery
AR3: Location | AS3: River and Hatchery
B4: Values | G4: percent | Z4: Brood Year | BD4: By Sex | BH4: By Cohort Escapement
A5: Year | B5: Sum of Raw_ESC_Age-3 | C5: Sum of Raw_ESC_Age-4 | D5: Sum of Raw_ESC_Age-5 | E5: Sum of Raw_ESC_Age-6 | F5: total | G5: 32 | H5: 42 | I5: 52 | J5: 62 | M5: Brood Year | N5: Age-32 | O5: Age-42 | P5: Age-52 | Q5: Age-62 | S5: Return Year | T5: Age-32 | U5: Age-42 | V5: Age-52 | W5: Age-62 | Y5: Return Year | Z5: 2004 | AA5: =1+Z5 -> 2005 | AB5: =1+AA5 -> 2006 | AC5: =1+AB5 -> 2007 | AD5: =1+AC5 -> 2008 | AE5: =1+AD5 -> 2009 | AF5: =1+AE5 -> 2010 | AG5: =1+AF5 -> 2011 | AH5: 2012 | AI5: 2013 | AJ5: 2014 | AK5: 2015 | AL5: 2016 | AM5: 2017 | AN5: 2018 | AO5: 2019 | AP5: 2020 | AQ5: 2021 | AS5: Values | AY5: Brood Year | AZ5: Age 3 | BA5: Age 4 | BB5: Age 5 | BC5: Age 6 | BD5: Age 3 | BE5: Age 4 | BF5: Age 5 | BG5: Age 6 | BH5: Age 3 | BI5: Age 4 | BJ5: Age 5 | BK5: Age 6
A6: 2010 | B6: 44.751014 | C6: 3880.8799 | D6: 3241.3351 | E6: 351.03397 | F6: =SUM(B6:E6) -> 7518 | G6: =B6/SUM($B6:$E6) -> 0.0059525159 | H6: =C6/SUM($B6:$E6) -> 0.51621174 | I6: =D6/SUM($B6:$E6) -> 0.43114328 | J6: =E6/SUM($B6:$E6) -> 0.046692468 | M6: 2007 | N6: =+B6 -> 44.751014 | O6: =+C7 -> 1405.2216 | P6: =+D8 -> 2626.4035 | Q6: =+E9 -> 40.184392 | S6: =+A6 -> 2010 | T6: =+B6 -> 44.751014 | U6: =+C6 -> 3880.8799 | V6: =+D6 -> 3241.3351 | W6: =+E6 -> 351.03397 | Y6: =+S6 -> 2010 | Z6: =+W6 -> 351.03397 | AA6: =+V6 -> 3241.3351 | AB6: =+U6 -> 3880.8799 | AC6: =+T6 -> 44.751014 | AR6: Year | AS6: Sum of Raw_ESC_Age-3 | AT6: Sum of Raw_ESC_Age-4 | AU6: Sum of Raw_ESC_Age-5 | AV6: Sum of Raw_ESC_Age-6 | AX6: 2007 | AY6: Males | AZ6: =+AS17+AS26 -> 6.1368421 | BA6: =+AT18 -> 936.17835 | BB6: =+AU19 -> 3522.2525 | BC6: =+AV24 -> 10.60479 | BD6: =+AZ6/SUM($AZ6:$BC6) -> 0.0013713085 | BE6: =+BA6/SUM($AZ6:$BC6) -> 0.2091938 | BF6: =+BB6/SUM($AZ6:$BC6) -> 0.78706519 | BG6: =+BC6/SUM($AZ6:$BC6) -> 0.0023696942 | BH6: =+AZ6/SUM($AZ6:$BC7) -> 0.00095899012 | BI6: =+BA6/SUM($AZ6:$BC7) -> 0.14629443 | BJ6: =+BB6/SUM($AZ6:$BC7) -> 0.55041425 | BK6: =+BC6/SUM($AZ6:$BC7) -> 0.0016571861
A7: 2011 | B7: 19 | C7: 1405.2216 | D7: 6811.3084 | E7: 179.47002 | F7: =SUM(B7:E7) -> 8415 | G7: =B7/SUM($B7:$E7) -> 0.0022578728 | H7: =C7/SUM($B7:$E7) -> 0.16699009 | I7: =D7/SUM($B7:$E7) -> 0.80942464 | J7: =E7/SUM($B7:$E7) -> 0.021327393 | M7: 2008 | N7: =+B7 -> 19 | O7: =+C8 -> 1411.3555 | P7: =+D9 -> 1486.2445 | Q7: =+E10 -> 129.94476 | S7: =+A7 -> 2011 | T7: =+B7 -> 19 | U7: =+C7 -> 1405.2216 | V7: =+D7 -> 6811.3084 | W7: =+E7 -> 179.47002 | Y7: =+S7 -> 2011 | AA7: =+W7 -> 179.47002 | AB7: =+V7 -> 6811.3084 | AC7: =+U7 -> 1405.2216 | AD7: =+T7 -> 19 | AR7: Adult Females | AS7: 31.407582 | AT7: 11935.918 | AU7: 26932.444 | AV7: 766.23034 | AY7: Females | AZ7: =+AS8 -> 0 | BA7: =+AT9 -> 578.33697 | BB7: =+AU10 -> 1316.1866 | BC7: =+AV11 -> 29.579602 | BD7: =+AZ7/SUM($AZ7:$BC7) -> 0 | BE7: =+BA7/SUM($AZ7:$BC7) -> 0.30057482 | BF7: =+BB7/SUM($AZ7:$BC7) -> 0.68405199 | BG7: =+BC7/SUM($AZ7:$BC7) -> 0.015373189 | BH7: =+AZ7/SUM($AZ6:$BC7) -> 0 | BI7: =+BA7/SUM($AZ6:$BC7) -> 0.09037538 | BJ7: =+BB7/SUM($AZ6:$BC7) -> 0.20567743 | BK7: =+BC7/SUM($AZ6:$BC7) -> 0.004622336
A8: 2012 | B8: 176.92207 | C8: 1411.3555 | D8: 2626.4035 | E8: 72.318953 | F8: =SUM(B8:E8) -> 4287 | G8: =B8/SUM($B8:$E8) -> 0.041269436 | H8: =C8/SUM($B8:$E8) -> 0.32921751 | I8: =D8/SUM($B8:$E8) -> 0.61264369 | J8: =E8/SUM($B8:$E8) -> 0.016869362 | M8: 2009 | N8: =+B8 -> 176.92207 | O8: =+C9 -> 2495.8152 | P8: =+D10 -> 7388.9483 | Q8: =+E11 -> 97.690702 | S8: =+A8 -> 2012 | T8: =+B8 -> 176.92207 | U8: =+C8 -> 1411.3555 | V8: =+D8 -> 2626.4035 | W8: =+E8 -> 72.318953 | Y8: =+S8 -> 2012 | AB8: =+W8 -> 72.318953 | AC8: =+V8 -> 2626.4035 | AD8: =+U8 -> 1411.3555 | AE8: =+T8 -> 176.92207 | AR8: 2010 | AS8: 0 | AT8: 1511.6921 | AU8: 2088.7085 | AV8: 211.59936 | AX8: 2008 | AY8: Males | AZ8: =+AS18+AS27 -> 0 | BA8: =+AT19 -> 1416.1138 | BB8: =+AU20 -> 22477.151 | BC8: =+AV20 -> 730.90629 | BD8: =+AZ8/SUM($AZ8:$BC8) -> 0 | BE8: =+BA8/SUM($AZ8:$BC8) -> 0.057509094 | BF8: =+BB8/SUM($AZ8:$BC8) -> 0.91280843 | BG8: =+BC8/SUM($AZ8:$BC8) -> 0.029682472 | BH8: =+AZ8/SUM($AZ8:$BC9) -> 0 | BI8: =+BA8/SUM($AZ8:$BC9) -> 0.05375275 | BJ8: =+BB8/SUM($AZ8:$BC9) -> 0.85318616 | BK8: =+BC8/SUM($AZ8:$BC9) -> 0.02774369
A9: 2013 | B9: 400.7559 | C9: 2495.8152 | D9: 1486.2445 | E9: 40.184392 | F9: =SUM(B9:E9) -> 4423 | G9: =B9/SUM($B9:$E9) -> 0.090607259 | H9: =C9/SUM($B9:$E9) -> 0.56428109 | I9: =D9/SUM($B9:$E9) -> 0.33602633 | J9: =E9/SUM($B9:$E9) -> 0.009085325 | M9: 2010 | N9: =+B9 -> 400.7559 | O9: =+C10 -> 5816.2648 | P9: =+D11 -> 7530.9115 | Q9: =+E12 -> 308.707 | S9: =+A9 -> 2013 | T9: =+B9 -> 400.7559 | U9: =+C9 -> 2495.8152 | V9: =+D9 -> 1486.2445 | W9: =+E9 -> 40.184392 | Y9: =+S9 -> 2013 | AC9: =+W9 -> 40.184392 | AD9: =+V9 -> 1486.2445 | AE9: =+U9 -> 2495.8152 | AF9: =+T9 -> 400.7559 | AR9: 2011 | AS9: 0 | AT9: 578.33697 | AU9: 4220.899 | AV9: 81.764009 | AY9: Females | AZ9: =+AS9 -> 0 | BA9: =+AT10 -> 720.72848 | BB9: =+AU11 -> 963.51119 | BC9: =+AV12 -> 36.544218 | BD9: =+AZ9/SUM($AZ9:$BC9) -> 0 | BE9: =+BA9/SUM($AZ9:$BC9) -> 0.4188373 | BF9: =+BB9/SUM($AZ9:$BC9) -> 0.55992574 | BG9: =+BC9/SUM($AZ9:$BC9) -> 0.021236959 | BH9: =+AZ9/SUM($AZ8:$BC9) -> 0 | BI9: =+BA9/SUM($AZ8:$BC9) -> 0.027357362 | BJ9: =+BB9/SUM($AZ8:$BC9) -> 0.036572891 | BK9: =+BC9/SUM($AZ8:$BC9) -> 0.0013871429
A10: 2014 | B10: 30.842105 | C10: 5816.2648 | D10: 7388.9483 | E10: 129.94476 | F10: =SUM(B10:E10) -> 13366 | G10: =B10/SUM($B10:$E10) -> 0.0023075045 | H10: =C10/SUM($B10:$E10) -> 0.43515374 | I10: =D10/SUM($B10:$E10) -> 0.55281672 | J10: =E10/SUM($B10:$E10) -> 0.0097220383 | M10: 2011 | N10: =+B10 -> 30.842105 | O10: =+C11 -> 3350.261 | P10: =+D12 -> 2613.9069 | Q10: =+E13 -> 200.94518 | S10: =+A10 -> 2014 | T10: =+B10 -> 30.842105 | U10: =+C10 -> 5816.2648 | V10: =+D10 -> 7388.9483 | W10: =+E10 -> 129.94476 | Y10: =+S10 -> 2014 | AD10: =+W10 -> 129.94476 | AE10: =+V10 -> 7388.9483 | AF10: =+U10 -> 5816.2648 | AG10: =+T10 -> 30.842105 | AR10: 2012 | AS10: 12.304348 | AT10: 720.72848 | AU10: 1316.1866 | AV10: 44.780593
A11: 2015 | B11: 19.136842 | C11: 3350.261 | D11: 7530.9115 | E11: 97.690702 | F11: =SUM(B11:E11) -> 10998 | G11: =B11/SUM($B11:$E11) -> 0.0017400293 | H11: =C11/SUM($B11:$E11) -> 0.30462457 | I11: =D11/SUM($B11:$E11) -> 0.68475282 | J11: =E11/SUM($B11:$E11) -> 0.0088825879 | M11: 2012 | N11: =+B11 -> 19.136842 | O11: =+C12 -> 1251.3861 | P11: =+D13 -> 1940.5083 | Q11: =+E14 -> 42.637323 | S11: 2015 | T11: =+B11 -> 19.136842 | U11: =+C11 -> 3350.261 | V11: =+D11 -> 7530.9115 | W11: =+E11 -> 97.690702 | Y11: =+S11 -> 2015 | AE11: =W11 -> 97.690702 | AF11: =V11 -> 7530.9115 | AG11: =U11 -> 3350.261 | AH11: =T11 -> 19.136842 | AR11: 2013 | AS11: 14.103234 | AT11: 1085.806 | AU11: 963.51119 | AV11: 29.579602
A12: 2016 | B12: 109 | C12: 1251.3861 | D12: 2613.9069 | E12: 308.707 | F12: =SUM(B12:E12) -> 4283 | G12: =B12/SUM($B12:$E12) -> 0.025449451 | H12: =C12/SUM($B12:$E12) -> 0.29217514 | I12: =D12/SUM($B12:$E12) -> 0.61029813 | J12: =E12/SUM($B12:$E12) -> 0.072077282 | M12: 2013 | N12: =+B12 -> 109 | O12: =+C13 -> 1540.0465 | P12: =+D14 -> 1049.9035 | Q12: =+E15 -> 77.821138 | S12: 2016 | T12: =+B12 -> 109 | U12: =+C12 -> 1251.3861 | V12: =+D12 -> 2613.9069 | W12: =+E12 -> 308.707 | Y12: =+S12 -> 2016 | AF12: =W12 -> 308.707 | AG12: =V12 -> 2613.9069 | AH12: =U12 -> 1251.3861 | AI12: =T12 -> 109 | AR12: 2014 | AS12: 0 | AT12: 2065.2224 | AU12: 4063.2333 | AV12: 36.544218
A13: 2017 | B13: 16.5 | C13: 1540.0465 | D13: 1940.5083 | E13: 200.94518 | F13: =SUM(B13:E13) -> 3698 | G13: =B13/SUM($B13:$E13) -> 0.0044618713 | H13: =C13/SUM($B13:$E13) -> 0.4164539 | I13: =D13/SUM($B13:$E13) -> 0.52474535 | J13: =E13/SUM($B13:$E13) -> 0.05433888 | M13: 2014 | N13: =+B13 -> 16.5 | O13: =+C14 -> 1203.4591 | P13: =+D15 -> 1059.0301 | Q13: =+E16 -> 0 | S13: 2017 | T13: =+B13 -> 16.5 | U13: =+C13 -> 1540.0465 | V13: =+D13 -> 1940.5083 | W13: =+E13 -> 200.94518 | Y13: =+S13 -> 2017 | AG13: =W13 -> 200.94518 | AH13: =V13 -> 1940.5083 | AI13: =U13 -> 1540.0465 | AJ13: =T13 -> 16.5 | AR13: 2015 | AS13: 0 | AT13: 1597.9014 | AU13: 4454.6408 | AV13: 41.457834
A14: 2018 | B14: 0 | C14: 1203.4591 | D14: 1049.9035 | E14: 42.637323 | F14: =SUM(B14:E14) -> 2296 | G14: =B14/SUM($B14:$E14) -> 0 | H14: =C14/SUM($B14:$E14) -> 0.52415467 | I14: =D14/SUM($B14:$E14) -> 0.45727506 | J14: =E14/SUM($B14:$E14) -> 0.018570263 | M14: 2015 | N14: =+B14 -> 0 | O14: =+C15 -> 1349.1488 | P14: =+D16 -> 4193.7759 | Q14: =+E17 -> 15.375 | S14: 2018 | T14: =+B14 -> 0 | U14: =+C14 -> 1203.4591 | V14: =+D14 -> 1049.9035 | W14: =+E14 -> 42.637323 | Y14: =+S14 -> 2018 | AH14: =W14 -> 42.637323 | AI14: =V14 -> 1049.9035 | AJ14: =U14 -> 1203.4591 | AK14: =T14 -> 0 | AR14: 2016 | AS14: 0 | AT14: 426.475 | AU14: 1398.018 | AV14: 132.507
A15: 2019 | B15: 0 | C15: 1349.1488 | D15: 1059.0301 | E15: 77.821138 | F15: =SUM(B15:E15) -> 2486 | G15: =B15/SUM($B15:$E15) -> 0 | H15: =C15/SUM($B15:$E15) -> 0.54269862 | I15: =D15/SUM($B15:$E15) -> 0.42599762 | J15: =E15/SUM($B15:$E15) -> 0.031303756 | M15: 2016 | N15: =+B15 -> 0 | O15: =+C16 -> 2118.2241 | P15: =+D17 -> 1879.0978 | Q15: =+E18 -> 58.829322 | S15: 2019 | T15: =+B15 -> 0 | U15: =+C15 -> 1349.1488 | V15: =+D15 -> 1059.0301 | W15: =+E15 -> 77.821138 | Y15: =+S15 -> 2019 | AI15: =W15 -> 77.821138 | AJ15: =V15 -> 1059.0301 | AK15: =U15 -> 1349.1488 | AL15: =T15 -> 0 | AR15: 2017 | AS15: 5 | AT15: 378.85976 | AU15: 1097.022 | AV15: 87.118293
A16: 2020 | B16: 143 | C16: 2118.2241 | D16: 4193.7759 | E16: 0 | F16: =SUM(B16:E16) -> 6455 | G16: =B16/SUM($B16:$E16) -> 0.022153369 | H16: =C16/SUM($B16:$E16) -> 0.32815245 | I16: =D16/SUM($B16:$E16) -> 0.64969418 | J16: =E16/SUM($B16:$E16) -> 0 | M16: 2017 | N16: =+B16 -> 143 | O16: =+C17 -> 3679.8311 | P16: =+D18 -> 8647.252 | Q16: =+E19 -> 40.609362 | S16: 2020 | T16: =+B16 -> 143 | U16: =+C16 -> 2118.2241 | V16: =+D16 -> 4193.7759 | W16: =+E16 -> 0 | Y16: =+S16 -> 2020 | AJ16: =W16 -> 0 | AK16: =V16 -> 4193.7759 | AL16: =U16 -> 2118.2241 | AM16: =T16 -> 143 | AR16: 2018 | AS16: 0 | AT16: 527.72725 | AU16: 678.40199 | AV16: 33.87076
A17: 2021 | B17: 99.696104 | C17: 3679.8311 | D17: 1879.0978 | E17: 15.375 | F17: =SUM(B17:E17) -> 5674 | G17: =B17/SUM($B17:$E17) -> 0.017570692 | H17: =C17/SUM($B17:$E17) -> 0.64854267 | I17: =D17/SUM($B17:$E17) -> 0.33117691 | J17: =E17/SUM($B17:$E17) -> 0.0027097286 | M17: 2018 | N17: =+B17 -> 99.696104 | O17: =+C18 -> 4837.1074 | P17: =+D19 -> 4423.655 | Q17: =+E20 -> 24.173077 | S17: 2021 | T17: =+B17 -> 99.696104 | U17: =+C17 -> 3679.8311 | V17: =+D17 -> 1879.0978 | W17: =+E17 -> 15.375 | Y17: =+S17 -> 2021 | AK17: =W17 -> 15.375 | AL17: =V17 -> 1879.0978 | AM17: =U17 -> 3679.8311 | AN17: =T17 -> 99.696104 | AR17: 2020 | AS17: 0 | AT17: 690.87635 | AU17: 2187.1236 | AV17: 0
A18: 2022 | B18: 331.81132 | C18: 4837.1074 | D18: 8647.252 | E18: 58.829322 | F18: =SUM(B18:E18) -> 13875 | G18: =B18/SUM($B18:$E18) -> 0.023914329 | H18: =C18/SUM($B18:$E18) -> 0.34862035 | I18: =D18/SUM($B18:$E18) -> 0.62322537 | J18: =E18/SUM($B18:$E18) -> 0.0042399512 | M18: 2019 | N18: =+B18 -> 331.81132 | O18: =+C19 -> 2933.3071 | P18: =+D20 -> 2055.6979 | S18: 2022 | T18: =+B18 -> 331.81132 | U18: =+C18 -> 4837.1074 | V18: =+D18 -> 8647.252 | W18: =+E18 -> 58.829322 | Y18: =+S18 -> 2022 | AL18: =W18 -> 58.829322 | AM18: =V18 -> 8647.252 | AN18: =U18 -> 4837.1074 | AO18: =T18 -> 331.81132 | AR18: 2021 | AS18: 0 | AT18: 936.17835 | AU18: 942.44665 | AV18: 15.375
A19: 2023 | B19: 351.42857 | C19: 2933.3071 | D19: 4423.655 | E19: 40.609362 | F19: =SUM(B19:E19) -> 7749 | G19: =B19/SUM($B19:$E19) -> 0.045351474 | H19: =C19/SUM($B19:$E19) -> 0.37854008 | I19: =D19/SUM($B19:$E19) -> 0.57086785 | J19: =E19/SUM($B19:$E19) -> 0.0052405938 | M19: 2020 | N19: =+B19 -> 351.42857 | O19: =+C20 -> 2665.4927 | S19: 2023 | T19: =+B19 -> 351.42857 | U19: =+C19 -> 2933.3071 | V19: =+D19 -> 4423.655 | W19: =+E19 -> 40.609362 | Y19: =+S19 -> 2023 | AN19: =V19 -> 4423.655 | AO19: =U19 -> 2933.3071 | AP19: =T19 -> 351.42857 | AR19: 2022 | AS19: 0 | AT19: 1416.1138 | AU19: 3522.2525 | AV19: 51.63367
A20: 2024 | B20: 230.63636 | C20: 2665.4927 | D20: 2055.6979 | E20: 24.173077 | F20: =SUM(B20:E20) -> 4976 | G20: =B20/SUM($B20:$E20) -> 0.046349752 | H20: =C20/SUM($B20:$E20) -> 0.53566975 | I20: =D20/SUM($B20:$E20) -> 0.41312257 | J20: =E20/SUM($B20:$E20) -> 0.0048579335 | M20: 2021 | N20: =+B20 -> 230.63636 | S20: 2024 | T20: =+B20 -> 230.63636 | U20: =+C20 -> 2665.4927 | V20: =+D20 -> 2055.6979 | W20: =+E20 -> 24.173077 | Y20: =+S20 -> 2024 | AN20: =W20 -> 24.173077 | AO20: =V20 -> 2055.6979 | AP20: =U20 -> 2665.4927 | AR20: Adult Males | AS20: 617.2298 | AT20: 20829.712 | AU20: 22477.151 | AV20: 730.90629
A21: Grand Total | B21: 1973.4803 | C21: 39937.801 | D21: 56947.979 | E21: 1639.7402 | AR21: 2010 | AS21: 37.751014 | AT21: 2348.1877 | AU21: 1152.6266 | AV21: 139.43461
AR22: 2011 | AS22: 0 | AT22: 826.88464 | AU22: 2590.4094 | AV22: 97.706007
AR23: 2012 | AS23: 132.61772 | AT23: 690.62698 | AU23: 1310.2169 | AV23: 27.53836
AR24: 2013 | AS24: 207.80652 | AT24: 1396.8554 | AU24: 522.73326 | AV24: 10.60479
AR25: 2014 | AS25: 10.842105 | AT25: 3751.0424 | AU25: 3325.715 | AV25: 93.400547
AR26: 2015 | AS26: 6.1368421 | AT26: 1752.3596 | AU26: 3076.2707 | AV26: 56.232868
AR27: 2016 | AS27: 0 | AT27: 824.91111 | AU27: 1215.8889 | AV27: 176.2
AR28: 2017 | AS28: 3 | AT28: 1152.6868 | AU28: 843.48634 | AV28: 113.82689
AR29: 2018 | AS29: 0 | AT29: 659.73188 | AU29: 371.50155 | AV29: 8.7665631
AR30: 2020 | AS30: 0 | AT30: 1427.3477 | AU30: 2006.6523 | AV30: 0
AR31: 2021 | AS31: 3.5142857 | AT31: 2641.8346 | AU31: 936.65113 | AV31: 0
AR32: 2022 | AS32: 215.56132 | AT32: 3357.2436 | AU32: 5124.9994 | AV32: 7.1956522
AR33: Jacks | AS33: 742.77797 | AT33: 224.22203 | AU33: 0 | AV33: 0
AR34: 2010 | AS34: 7 | AT34: 21 | AU34: 0 | AV34: 0
AR35: 2011 | AS35: 19 | AT35: 0 | AU35: 0 | AV35: 0
AR36: 2012 | AS36: 32 | AT36: 0 | AU36: 0 | AV36: 0
AR37: 2013 | AS37: 178.84615 | AT37: 13.153846 | AU37: 0 | AV37: 0
AR38: 2014 | AS38: 20 | AT38: 0 | AU38: 0 | AV38: 0
AR39: 2015 | AS39: 13 | AT39: 0 | AU39: 0 | AV39: 0
AR40: 2016 | AS40: 109 | AT40: 0 | AU40: 0 | AV40: 0
...

Sheet Notes
A2: Unclipped petersen tagged stratum Estimate = tags applied
A3: Clipped aged totals may also be petersen tagged
A7: 2017
A8: One CWT was recovered. This fish was caught while seining and culled to sample the head. The fish was 50.1 cm, making it fall into the large male category. Age results showed the fish to be a jack, which was expected due to the first cwt release being from the 2014 brood.
A9: spreadsheet converted to this version. Old sheet did not have any hatchery info or scale/cwt correction
A10: Fish sacrificed at application are included in the hatchery removals rows
A12: 2018
A13: scale results show high number of 31 and 41 ages. These ages are NOT included in this spreadsheet. Scale re-reads of the sub 1s were done by the lab, only a few were changed
A15: Count of GR-Age | B15: Column Labels
A16: Row Labels | B16: 31 | C16: 41 | D16: 42 | E16: 52 | F16: 53 | G16: 62 | H16: Grand Total
A17: F | B17: 3 | C17: 32 | D17: 131 | E17: 169 | G17: 10 | H17: 345
A18: J | D18: 1 | H18: 1
A19: M | B19: 11 | C19: 17 | D19: 139 | E19: 77 | F19: 1 | G19: 2 | H19: 247
A20: Grand Total | B20: 14 | C20: 49 | D20: 271 | E20: 246 | F20: 1 | G20: 12 | H20: 593
A22: the one jack with scale sample results says it was age 42. The poh was 38cm, the age does not seem right. This causes all the jacks to correct to age 42
A24: the three aged 31 females had poh lengths of over 57cm, which does not seem to match the age results. These fish are not used in the spreadsheet anyways as they are sub 1's
A26: Fish sacrificed at application are included in the hatchery removals rows
A29: 2019
A30: No mark recapture conducted due to Big Bar Slide. Calibrated peak count estimate used.
A31: No estimate by sex.
A32: See below for age breakdown by sex
A33: One 32 (jack) not included due to no jack estimate
G34: Age Samples from Scales or CWTs (only for AFC strata) | L34: Uncorrected Escapement by Age and Stratum
A35: Location | B35: Stratum | C35: AFC Status | D35: Petersen Tagged | E35: Year | F35: Stratum Estimate | G35: Age-3 | H35: Age-4 | I35: Age-5 | J35: Age-6 | K35: Raw_ESC_Age-3 | L35: Raw_ESC_Age-4 | M35: Raw_ESC_Age-5 | N35: Raw_ESC_Age-6
A36: River | B36: Adult Males | C36: Clipped | D36: NA | E36: 2019 | H36: 1 | I36: 1 | K36: =+(G36/(SUM($G36:$J36)))*$F36 -> 0 | L36: =+(H36/(SUM($G36:$J36)))*$F36 -> 0 | M36: =+(I36/(SUM($G36:$J36)))*$F36 -> 0 | N36: =+(J36/(SUM($G36:$J36)))*$F36 -> 0
A37: River | B37: Adult Males | C37: Unclipped | D37: Petersen Tagged | E37: 2019 | K37: =+(G37/(SUM($G37:$J37)))*$F37 -> #DIV/0! | L37: =+(H37/(SUM($G37:$J37)))*$F37 -> #DIV/0! | M37: =+(I37/(SUM($G37:$J37)))*$F37 -> #DIV/0! | N37: =+(J37/(SUM($G37:$J37)))*$F37 -> #DIV/0!
A38: River | B38: Adult Males | C38: Unclipped | D38: No Petersen Tag | E38: 2019 | F38: =+F41-SUM(F36:F37) -> 0 | H38: 31 | I38: 13 | J38: 2 | K38: =+(G38/(SUM($G38:$J38)))*$F38 -> 0 | L38: =+(H38/(SUM($G38:$J38)))*$F38 -> 0 | M38: =+(I38/(SUM($G38:$J38)))*$F38 -> 0 | N38: =+(J38/(SUM($G38:$J38)))*$F38 -> 0
A39: Hatchery | B39: Adult Males | C39: Clipped | D39: No Petersen Tag | E39: 2019 | K39: =+IF($F39=0,0,(G39/(SUM($G39:$J39)))*$F39) -> 0 | L39: =+IF($F39=0,0,(H39/(SUM($G39:$J39)))*$F39) -> 0 | M39: =+IF($F39=0,0,(I39/(SUM($G39:$J39)))*$F39) -> 0 | N39: =+IF($F39=0,0,(J39/(SUM($G39:$J39)))*$F39) -> 0
A40: Hatchery | B40: Adult Males | C40: Unclipped | D40: No Petersen Tag | E40: 2019 | K40: =+IF(G40="",(G38/(SUM($G38:$J38)))*$F40,(G40/(SUM($G40:$J40)))*$F40) -> 0 | L40: =+IF(H40="",(H38/(SUM($G38:$J38)))*$F40,(H40/(SUM($G40:$J40)))*$F40) -> 0 | M40: =+IF(I40="",(I38/(SUM($G38:$J38)))*$F40,(I40/(SUM($G40:$J40)))*$F40) -> 0 | N40: =+IF(J40="",(J38/(SUM($G38:$J38)))*$F40,(J40/(SUM($G40:$J40)))*$F40) -> 0
A41: River | B41: Adult Males | C41: both | D41: both | E41: 2019 | K41: =+SUM(K36:K38) -> #DIV/0! | L41: =+SUM(L36:L38) -> #DIV/0! | M41: =+SUM(M36:M38) -> #DIV/0! | N41: =+SUM(N36:N38) -> #DIV/0!
A42: River and Hatchery | B42: Adult Males | C42: both | D42: both | E42: 2019 | F42: =F41+SUM(F39:F40) -> 0 | K42: =SUM(K36:K40) -> #DIV/0! | L42: =SUM(L36:L40) -> #DIV/0! | M42: =SUM(M36:M40) -> #DIV/0! | N42: =SUM(N36:N40) -> #DIV/0!
A44: River | B44: Adult Females | C44: Clipped | D44: NA | E44: 2019 | H44: 6 | I44: 2 | K44: =+(G44/(SUM($G44:$J44)))*$F44 -> 0 | L44: =+(H44/(SUM($G44:$J44)))*$F44 -> 0 | M44: =+(I44/(SUM($G44:$J44)))*$F44 -> 0 | N44: =+(J44/(SUM($G44:$J44)))*$F44 -> 0
A45: River | B45: Adult Females | C45: Unclipped | D45: Petersen Tagged | E45: 2019 | K45: =+(G45/(SUM($G45:$J45)))*$F45 -> #DIV/0! | L45: =+(H45/(SUM($G45:$J45)))*$F45 -> #DIV/0! | M45: =+(I45/(SUM($G45:$J45)))*$F45 -> #DIV/0! | N45: =+(J45/(SUM($G45:$J45)))*$F45 -> #DIV/0!
A46: River | B46: Adult Females | C46: Unclipped | D46: No Petersen Tag | E46: 2019 | F46: =+F49-SUM(F44:F45) -> 0 | H46: 35 | I46: 40 | J46: 2 | K46: =+(G46/(SUM($G46:$J46)))*$F46 -> 0 | L46: =+(H46/(SUM($G46:$J46)))*$F46 -> 0 | M46: =+(I46/(SUM($G46:$J46)))*$F46 -> 0 | N46: =+(J46/(SUM($G46:$J46)))*$F46 -> 0
A47: Hatchery | B47: Adult Females | C47: Clipped | D47: No Petersen Tag | E47: 2019 | K47: =+IF($F47=0,0,(G47/(SUM($G47:$J47)))*$F47) -> 0 | L47: =+IF($F47=0,0,(H47/(SUM($G47:$J47)))*$F47) -> 0 | M47: =+IF($F47=0,0,(I47/(SUM($G47:$J47)))*$F47) -> 0 | N47: =+IF($F47=0,0,(J47/(SUM($G47:$J47)))*$F47) -> 0
A48: Hatchery | B48: Adult Females | C48: Unclipped | D48: No Petersen Tag | E48: 2019 | K48: =+IF(G48="",(G46/(SUM($G46:$J46)))*$F48,(G48/(SUM($G48:$J48)))*$F48) -> 0 | L48: =+IF(H48="",(H46/(SUM($G46:$J46)))*$F48,(H48/(SUM($G48:$J48)))*$F48) -> 0 | M48: =+IF(I48="",(I46/(SUM($G46:$J46)))*$F48,(I48/(SUM($G48:$J48)))*$F48) -> 0 | N48: =+IF(J48="",(J46/(SUM($G46:$J46)))*$F48,(J48/(SUM($G48:$J48)))*$F48) -> 0
A49: River | B49: Adult Females | C49: both | D49: both | E49: 2019 | K49: =+SUM(K44:K46) -> #DIV/0! | L49: =+SUM(L44:L46) -> #DIV/0! | M49: =+SUM(M44:M46) -> #DIV/0! | N49: =+SUM(N44:N46) -> #DIV/0!
A50: River and Hatchery | B50: Adult Females | C50: both | D50: both | E50: 2019 | F50: =F49+SUM(F47:F48) -> 0 | K50: =SUM(K44:K48) -> #DIV/0! | L50: =SUM(L44:L48) -> #DIV/0! | M50: =SUM(M44:M48) -> #DIV/0! | N50: =SUM(N44:N48) -> #DIV/0!
A52: River | B52: Jacks | C52: Clipped | D52: NA | E52: 2019
A53: River | B53: Jacks | C53: Unclipped | D53: Petersen Tagged | E53: 2019 | K53: =+IF(G53="",(G54/(SUM($G54:$J54)))*$F53,(G53/(SUM($G53:$J53)))*$F53) -> 0 | L53: =+IF(H53="",(H54/(SUM($G54:$J54)))*$F53,(H53/(SUM($G53:$J53)))*$F53) -> 0 | M53: =+IF(I53="",(I54/(SUM($G54:$J54)))*$F53,(I53/(SUM($G53:$J53)))*$F53) -> 0 | N53: =+IF(J53="",(J54/(SUM($G54:$J54)))*$F53,(J53/(SUM($G53:$J53)))*$F53) -> 0
...

Sheet Sheet1
A3: Average of unclipped fish
A4: year | B4: age | C4: brood year | D4: identifier | E4: Total
A5: 2010 | B5: 3 | C5: 2007 | D5: 2010.3 | E5: 44.751014
B6: 4 | C6: 2006 | D6: 2010.4 | E6: 3880.8799
B7: 5 | C7: 2005 | D7: 2010.5 | E7: 3241.3351
B8: 6 | C8: 2004 | D8: 2010.6 | E8: 351.03397
A9: 2011 | B9: 3 | C9: 2008 | D9: 2011.3 | E9: 19
B10: 4 | C10: 2007 | D10: 2011.4 | E10: 1405.2216
B11: 5 | C11: 2006 | D11: 2011.5 | E11: 6811.3084
B12: 6 | C12: 2005 | D12: 2011.6 | E12: 179.47002
A13: 2012 | B13: 3 | C13: 2009 | D13: 2012.3 | E13: 176.92207
B14: 4 | C14: 2008 | D14: 2012.4 | E14: 1411.3555
B15: 5 | C15: 2007 | D15: 2012.5 | E15: 2626.4035
B16: 6 | C16: 2006 | D16: 2012.6 | E16: 72.318953
A17: 2013 | B17: 3 | C17: 2010 | D17: 2013.3 | E17: 400.7559
B18: 4 | C18: 2009 | D18: 2013.4 | E18: 2495.8152
B19: 5 | C19: 2008 | D19: 2013.5 | E19: 1486.2445
B20: 6 | C20: 2007 | D20: 2013.6 | E20: 40.184392
A21: 2014 | B21: 3 | C21: 2011 | D21: 2014.3 | E21: 30.842105
B22: 4 | C22: 2010 | D22: 2014.4 | E22: 5816.2648
B23: 5 | C23: 2009 | D23: 2014.5 | E23: 7388.9483
B24: 6 | C24: 2008 | D24: 2014.6 | E24: 129.94476
A25: 2015 | B25: 3 | C25: 2012 | D25: 2015.3 | E25: 19.136842
B26: 4 | C26: 2011 | D26: 2015.4 | E26: 3350.261
B27: 5 | C27: 2010 | D27: 2015.5 | E27: 7530.9115
B28: 6 | C28: 2009 | D28: 2015.6 | E28: 97.690702
A29: 2016 | B29: 3 | C29: 2013 | D29: 2016.3 | E29: 109
B30: 4 | C30: 2012 | D30: 2016.4 | E30: 1251.3861
B31: 5 | C31: 2011 | D31: 2016.5 | E31: 2613.9069
B32: 6 | C32: 2010 | D32: 2016.6 | E32: 308.707
A33: 2017 | B33: 3 | C33: 2014 | D33: 2017.3 | E33: 8.5
B34: 4 | C34: 2013 | D34: 2017.4 | E34: 1540.0465
B35: 5 | C35: 2012 | D35: 2017.5 | E35: 1940.5083
B36: 6 | C36: 2011 | D36: 2017.6 | E36: 200.94518
A37: 2018 | B37: 3 | C37: 2015 | D37: 2018.3 | E37: 0
B38: 4 | C38: 2014 | D38: 2018.4 | E38: 1125.4591
B39: 5 | C39: 2013 | D39: 2018.5 | E39: 1049.9035
B40: 6 | C40: 2012 | D40: 2018.6 | E40: 42.637323
A41: (blank) | B41: (blank) | C41: (blank) | D41: (blank)
A42: 2019 | B42: 3 | C42: 2016 | D42: 2019.3 | E42: 0
...

Sheet Cdn CWTs for ERA in 2021
A1: Tag Codes for the Canadian indicators up to BY 2008 (or 2007 depending on stock) to be used for the ERA and forecasts in 2011
A2: Included are:
A3: Standard indicator codes
A4: Codes used only for the base period calibration
A5: Additional codes for testing (new)
A7: Stock Acr | B7: BY | C7: CWT | D7: DIT? | E7: Clip Status | F7: BY | G7: indicator? | H7: Stock | I7: Stock Acronym | J7: Stock Site/Name | K7: Hatchery Site Code-Name | L7: Run Type | M7: Run Type Name | N7: Start Age | O7: Max Age | P7: Region | U7: brood_year | V7: tag_code_or_release_id
